Workbook

Sheet original_dataset
A1: store_id | B1: month | C1: region | D1: store_type | E1: marketing_spend | F1: footfall | G1: avg_discount_pct | H1: staff_count | I1: inventory_availability_pct | J1: competitor_distance_km | K1: holiday_flag | L1: customer_rating | M1: monthly_sales | N1: monthly_profit
A2: STR-1001 | B2: 2025-01-01 | C2: East | D2: Residential | E2: 70389.11 | F2: 8302 | G2: 0.042 | H2: 17 | I2: 75 | J2: 5.28 | K2: 1 | L2: 3.1 | M2: 658832.62 | N2: 84349.93
A3: STR-1001 | B3: 2025-02-01 | C3: East | D3: Residential | E3: 43827.89 | F3: 8487 | G3: 0.168 | H3: 23 | I3: 84.4 | J3: 4.31 | K3: 0 | L3: 2.8 | M3: 634436 | N3: 106130.54
A4: STR-1001 | B4: 2025-03-01 | C4: East | D4: Residential | E4: 59921.75 | F4: 9113 | G4: 0.133 | H4: 20 | I4: 88 | J4: 12 | K4: 0 | L4: 3.2 | M4: 678722.06 | N4: 101883.86
A5: STR-1001 | B5: 2025-04-01 | C5: East | D5: Residential | E5: 56856.63 | F5: 9431 | G5: 0.142 | H5: 23 | I5: 86.9 | J5: 4.97 | K5: 0 | L5: 3.4 | M5: 658920.3 | N5: 97910.37
A6: STR-1002 | B6: 2025-01-01 | C6: East | D6: High Street | E6: 48412.64 | F6: 9545 | G6: 0.231 | H6: 21 | I6: 97.6 | J6: 6.94 | K6: 1 | L6: 4.2 | M6: 741341.44 | N6: 119208.17
A7: STR-1002 | B7: 2025-02-01 | C7: East | D7: High Street | E7: 64811.21 | F7: 9792 | G7: 0.112 | H7: 20 | I7: 84.2 | J7: 2.88 | K7: 0 | L7: 4.2 | M7: 761835.34 | N7: 149602.23
A8: STR-1002 | B8: 2025-03-01 | C8: East | D8: High Street | E8: 46213.45 | F8: 10616 | G8: 0.122 | H8: 22 | I8: 85.2 | J8: 0.2 | K8: 1 | L8: 4.1 | M8: 806615.54 | N8: 131364.62
A9: STR-1002 | B9: 2025-04-01 | C9: East | D9: High Street | E9: 68148.52 | F9: 8567 | G9: 0.127 | H9: 23 | I9: 95.6 | J9: 0.8 | K9: 0 | L9: 3.9 | M9: 850164.26 | N9: 149262.75
A10: STR-1003 | B10: 2025-01-01 | C10: North | D10: Airport | E10: 71838.86 | F10: 10979 | G10: 0.215 | H10: 26 | I10: 88.6 | J10: 7.7 | K10: 1 | L10: 3.8 | M10: 930581.7 | N10: 136207.98
A11: STR-1003 | B11: 2025-02-01 | C11: North | D11: Airport | E11: 68133.44 | F11: 9459 | G11: 0.22 | H11: 21 | I11: 85 | J11: 1.91 | K11: 0 | L11: 4.2 | M11: 779010.94 | N11: 106328.09
A12: STR-1003 | B12: 2025-03-01 | C12: North | D12: Airport | E12: 34285.21 | F12: 9172 | G12: 0.213 | H12: 22 | I12: 88.3 | J12: 10.46 | K12: 1 | L12: 3.8 | M12: 723060.76 | N12: 123131.24
A13: STR-1003 | B13: 2025-04-01 | C13: North | D13: Airport | E13: 67979.88 | F13: 11230 | G13: 0.002 | H13: 28 | I13: 85.3 | J13: 7.16 | K13: 0 | L13: 3.8 | M13: 910791.94 | N13: 158891.28
... A34: STR-1009 | B34: 2025-01-01 | C34: North | D34: Residential | E34: 54597.83 | F34: 9429 | G34: 0.188 | H34: 21 | I34: 83.3 | J34: 11.71 | K34: 0 | L34: 4.2 | M34: 641865.03 | N34: 81342.58
A35: STR-1009 | B35: 2025-02-01 | C35: North | D35: Residential | E35: 73771.91 | F35: 11695 | G35: 0.07 | H35: 25 | I35: 84.7 | J35: 0.62 | K35: 0 | M35: 799477.76 | N35: 164974.41
A36: STR-1009 | B36: 2025-03-01 | C36: North | D36: Residential | E36: 74413.88 | F36: 9449 | G36: 0.039 | H36: 23 | I36: 92.1 | J36: 2.12 | K36: 0 | L36: 3.5 | M36: 798952.17 | N36: 161499.04
A37: STR-1009 | B37: 2025-04-01 | C37: North | D37: Residential | E37: 52483.77 | F37: 10453 | G37: 0.247 | H37: 25 | I37: 99 | J37: 6.31 | K37: 0 | L37: 3.6 | M37: 800979.78 | N37: 149242.27
A38: STR-1010 | B38: 2025-01-01 | C38: North | D38: Mall | E38: 75269.87 | F38: 8838 | G38: 0.092 | H38: 21 | I38: 83.1 | J38: 9.56 | K38: 1 | L38: 4.2 | M38: 820593.93 | N38: 115860.06
A39: STR-1010 | B39: 2025-02-01 | C39: North | D39: Mall | E39: 61245.41 | F39: 8156 | G39: 0.156 | H39: 19 | I39: 92.9 | J39: 9.05 | K39: 0 | L39: 3.8 | M39: 718330.53 | N39: 93247.9
A40: STR-1010 | B40: 2025-03-01 | C40: North | D40: Mall | E40: 93381.26 | F40: 7562 | G40: 0.198 | H40: 19 | I40: 82.9 | J40: 5.05 | K40: 0 | L40: 4 | M40: 736633.4 | N40: 115654.66
A41: STR-1010 | B41: 2025-04-01 | C41: North | D41: Mall | E41: 65012.19 | F41: 9598 | G41: 0.085 | H41: 24 | I41: 98.3 | J41: 0.89 | K41: 0 | L41: 3.8 | M41: 828623.85 | N41: 167320.52
A42: STR-1011 | B42: 2025-01-01 | C42: East | D42: Mall | E42: 40462.94 | F42: 3660 | G42: 0.218 | H42: 11 | I42: 95.2 | J42: 5.57 | K42: 0 | L42: 4.4 | M42: 592195.85 | N42: 92291.56
A43: STR-1011 | B43: 2025-02-01 | C43: East | D43: Mall | E43: 46123.88 | F43: 3227 | G43: 0.143 | H43: 10 | I43: 75.4 | J43: 1.06 | K43: 0 | L43: 4.4 | M43: 532644.46 | N43: 60681.32
A44: STR-1011 | B44: 2025-03-01 | C44: East | D44: Mall | E44: 68077.54 | F44: 3360 | G44: 0.128 | H44: 14 | I44: 88.2 | J44: 1.24 | K44: 1 | L44: 4 | M44: 657429.18 | N44: 88919.74
A45: STR-1011 | B45: 2025-04-01 | C45: East | D45: Mall | E45: 64882.14 | F45: 3642 | G45: 0.019 | H45: 13 | I45: 87.8 | J45: 4.52 | K45: 0 | L45: 4.2 | M45: 605178 | N45: 106958.74
A46: STR-1012 | B46: 2025-01-01 | C46: West | D46: Residential | E46: 138855.51 | F46: 5145 | G46: 0.06 | H46: 17 | I46: 88.2 | J46: 9.58 | K46: 0 | L46: 3.2 | M46: 595467.6 | N46: 104276.46
A47: STR-1012 | B47: 2025-02-01 | C47: West | D47: Residential | E47: 63630.21 | F47: 4460 | G47: 0.235 | H47: 14 | I47: 98.6 | J47: 5.52 | K47: 0 | L47: 3.5 | M47: 599603.4 | N47: 112685.12
... A72: STR-1018 | B72: 2025-03-01 | C72: East | D72: High Street | E72: 60571.82 | F72: 3193 | G72: 0.197 | H72: 7 | I72: 99 | J72: 1.43 | K72: 0 | L72: 3.2 | M72: 605023.87 | N72: 98545.81
A73: STR-1018 | B73: 2025-04-01 | C73: East | D73: High Street | E73: 55081.16 | F73: 5485 | G73: 0.036 | H73: 12 | I73: 88 | K73: 0 | L73: 3.5 | M73: 674774.09 | N73: 141917.59
A74: STR-1019 | B74: 2025-01-01 | C74: East | D74: Residential | E74: 46201.46 | F74: 5918 | G74: 0.277 | H74: 13 | I74: 78.8 | J74: 4.91 | K74: 0 | L74: 4.5 | M74: 616069.41 | N74: 54453.99
A75: STR-1019 | B75: 2025-02-01 | C75: East | D75: Residential | E75: 53762.92 | F75: 6821 | G75: 0.066 | H75: 19 | I75: 94.6 | J75: 7.03 | K75: 0 | L75: 4.4 | M75: 630829.94 | N75: 117090.02
A76: STR-1019 | B76: 2025-03-01 | C76: East | D76: Residential | E76: 70144.78 | F76: 6806 | G76: 0.178 | H76: 20 | I76: 93.1 | J76: 0.28 | K76: 1 | L76: 4.3 | M76: 788087.68 | N76: 116803.42
A77: STR-1019 | B77: 2025-04-01 | C77: East | D77: Residential | E77: 58749.63 | F77: 8252 | G77: 0.203 | H77: 20 | I77: 85.2 | J77: 3.61 | K77: 0 | L77: 4.5 | M77: 680840.36 | N77: 68007.68
A78: STR-1020 | B78: 2025-01-01 | C78: South | D78: High Street | E78: 56973.18 | F78: 6662 | G78: 0.1 | H78: 15 | I78: 77.7 | J78: 7.52 | K78: 1 | L78: 3.2 | M78: 643657.47 | N78: 87022.45
A79: STR-1020 | B79: 2025-02-01 | C79: South | D79: High Street | E79: 54872.82 | F79: 5962 | G79: 0.064 | H79: 12 | I79: 85.4 | J79: 2.58 | K79: 0 | L79: 2.9 | M79: 691112.6 | N79: 109212.83
A80: STR-1020 | B80: 2025-03-01 | C80: South | D80: High Street | E80: 80562.81 | F80: 7470 | G80: 0.172 | H80: 16 | I80: 83.5 | J80: 2.29 | K80: 0 | L80: 3.3 | M80: 776922.17 | N80: 150701.93
A81: STR-1020 | B81: 2025-04-01 | C81: South | D81: High Street | E81: 77999.9 | F81: 5974 | G81: 0.252 | H81: 14 | I81: 81.3 | J81: 2.39 | K81: 0 | L81: 3.2 | M81: 636561.34 | N81: 93861.06
A82: STR-1021 | B82: 2025-01-01 | C82: West | D82: Mall | E82: 60881.01 | F82: 5410 | G82: 0.179 | H82: 15 | I82: 83.9 | J82: 5.24 | K82: 0 | L82: 4.6 | M82: 621369.58 | N82: 85493.64
A83: STR-1021 | B83: 2025-02-01 | C83: West | D83: Mall | E83: 60628.38 | F83: 4451 | G83: 0.095 | H83: 10 | I83: 89.6 | J83: 3.17 | K83: 0 | L83: 4.6 | M83: 682208.01 | N83: 110318.84
A84: STR-1021 | B84: 2025-03-01 | C84: West | D84: Mall | E84: 72731.14 | F84: 4644 | G84: 0.084 | H84: 15 | I84: 87.1 | J84: 2.66 | K84: 0 | L84: 4.6 | M84: 727241.86 | N84: 155810.3
...

Sheet cleaned_data
A1: store_id | B1: month | C1: region | D1: store_type | E1: marketing_spend | F1: footfall | G1: avg_discount_pct | H1: staff_count | I1: inventory_availability_pct | J1: competitor_distance_km | K1: holiday_flag | L1: customer_rating | M1: monthly_sales | N1: monthly_profit | O1: imputed_competitor_distance | P1: imputed_customer_rating
A2: =original_dataset!A2 -> STR-1001 | B2: =original_dataset!B2 -> 2025-01-01 | C2: =original_dataset!C2 -> East | D2: =original_dataset!D2 -> Residential | E2: =original_dataset!E2 -> 70389.11 | F2: =original_dataset!F2 -> 8302 | G2: =original_dataset!G2 -> 0.042 | H2: =original_dataset!H2 -> 17 | I2: =original_dataset!I2 -> 75 | J2: =IF(ISBLANK(original_dataset!J2),MEDIAN(original_dataset!$J$2:$J$321),original_dataset!J2) -> 5.28 | K2: =original_dataset!K2 -> 1 | L2: =IF(ISBLANK(original_dataset!L2),MEDIAN(original_dataset!$L$2:$L$321),original_dataset!L2) -> 3.1 | M2: =original_dataset!M2 -> 658832.62 | N2: =original_dataset!N2 -> 84349.93 | O2: =IF(ISBLANK(original_dataset!J2),"Yes","No") -> No | P2: =IF(ISBLANK(original_dataset!L2),"Yes","No") -> No
A3: =original_dataset!A3 -> STR-1001 | B3: =original_dataset!B3 -> 2025-02-01 | C3: =original_dataset!C3 -> East | D3: =original_dataset!D3 -> Residential | E3: =original_dataset!E3 -> 43827.89 | F3: =original_dataset!F3 -> 8487 | G3: =original_dataset!G3 -> 0.168 | H3: =original_dataset!H3 -> 23 | I3: =original_dataset!I3 -> 84.4 | J3: =IF(ISBLANK(original_dataset!J3),MEDIAN(original_dataset!$J$2:$J$321),original_dataset!J3) -> 4.31 | K3: =original_dataset!K3 -> 0 | L3: =IF(ISBLANK(original_dataset!L3),MEDIAN(original_dataset!$L$2:$L$321),original_dataset!L3) -> 2.8 | M3: =original_dataset!M3 -> 634436 | N3: =original_dataset!N3 -> 106130.54 | O3: =IF(ISBLANK(original_dataset!J3),"Yes","No") -> No | P3: =IF(ISBLANK(original_dataset!L3),"Yes","No") -> No
A4: =original_dataset!A4 -> STR-1001 | B4: =original_dataset!B4 -> 2025-03-01 | C4: =original_dataset!C4 -> East | D4: =original_dataset!D4 -> Residential | E4: =original_dataset!E4 -> 59921.75 | F4: =original_dataset!F4 -> 9113 | G4: =original_dataset!G4 -> 0.133 | H4: =original_dataset!H4 -> 20 | I4: =original_dataset!I4 -> 88 | J4: =IF(ISBLANK(original_dataset!J4),MEDIAN(original_dataset!$J$2:$J$321),original_dataset!J4) -> 12 | K4: =original_dataset!K4 -> 0 | L4: =IF(ISBLANK(original_dataset!L4),MEDIAN(original_dataset!$L$2:$L$321),original_dataset!L4) -> 3.2 | M4: =original_dataset!M4 -> 678722.06 | N4: =original_dataset!N4 -> 101883.86 | O4: =IF(ISBLANK(original_dataset!J4),"Yes","No") -> No | P4: =IF(ISBLANK(original_dataset!L4),"Yes","No") -> No
A5: =original_dataset!A5 -> STR-1001 | B5: =original_dataset!B5 -> 2025-04-01 | C5: =original_dataset!C5 -> East | D5: =original_dataset!D5 -> Residential | E5: =original_dataset!E5 -> 56856.63 | F5: =original_dataset!F5 -> 9431 | G5: =original_dataset!G5 -> 0.142 | H5: =original_dataset!H5 -> 23 | I5: =original_dataset!I5 -> 86.9 | J5: =IF(ISBLANK(original_dataset!J5),MEDIAN(original_dataset!$J$2:$J$321),original_dataset!J5) -> 4.97 | K5: =original_dataset!K5 -> 0 | L5: =IF(ISBLANK(original_dataset!L5),MEDIAN(original_dataset!$L$2:$L$321),original_dataset!L5) -> 3.4 | M5: =original_dataset!M5 -> 658920.3 | N5: =original_dataset!N5 -> 97910.37 | O5: =IF(ISBLANK(original_dataset!J5),"Yes","No") -> No | P5: =IF(ISBLANK(original_dataset!L5),"Yes","No") -> No
A6: =original_dataset!A6 -> STR-1002 | B6: =original_dataset!B6 -> 2025-01-01 | C6: =original_dataset!C6 -> East | D6: =original_dataset!D6 -> High Street | E6: =original_dataset!E6 -> 48412.64 | F6: =original_dataset!F6 -> 9545 | G6: =original_dataset!G6 -> 0.231 | H6: =original_dataset!H6 -> 21 | I6: =original_dataset!I6 -> 97.6 | J6: =IF(ISBLANK(original_dataset!J6),MEDIAN(original_dataset!$J$2:$J$321),original_dataset!J6) -> 6.94 | K6: =original_dataset!K6 -> 1 | L6: =IF(ISBLANK(original_dataset!L6),MEDIAN(original_dataset!$L$2:$L$321),original_dataset!L6) -> 4.2 | M6: =original_dataset!M6 -> 741341.44 | N6: =original_dataset!N6 -> 119208.17 | O6: =IF(ISBLANK(original_dataset!J6),"Yes","No") -> No | P6: =IF(ISBLANK(original_dataset!L6),"Yes","No") -> No
A7: =original_dataset!A7 -> STR-1002 | B7: =original_dataset!B7 -> 2025-02-01 | C7: =original_dataset!C7 -> East | D7: =original_dataset!D7 -> High Street | E7: =original_dataset!E7 -> 64811.21 | F7: =original_dataset!F7 -> 9792 | G7: =original_dataset!G7 -> 0.112 | H7: =original_dataset!H7 -> 20 | I7: =original_dataset!I7 -> 84.2 | J7: =IF(ISBLANK(original_dataset!J7),MEDIAN(original_dataset!$J$2:$J$321),original_dataset!J7) -> 2.88 | K7: =original_dataset!K7 -> 0 | L7: =IF(ISBLANK(original_dataset!L7),MEDIAN(original_dataset!$L$2:$L$321),original_dataset!L7) -> 4.2 | M7: =original_dataset!M7 -> 761835.34 | N7: =original_dataset!N7 -> 149602.23 | O7: =IF(ISBLANK(original_dataset!J7),"Yes","No") -> No | P7: =IF(ISBLANK(original_dataset!L7),"Yes","No") -> No
A8: =original_dataset!A8 -> STR-1002 | B8: =original_dataset!B8 -> 2025-03-01 | C8: =original_dataset!C8 -> East | D8: =original_dataset!D8 -> High Street | E8: =original_dataset!E8 -> 46213.45 | F8: =original_dataset!F8 -> 10616 | G8: =original_dataset!G8 -> 0.122 | H8: =original_dataset!H8 -> 22 | I8: =original_dataset!I8 -> 85.2 | J8: =IF(ISBLANK(original_dataset!J8),MEDIAN(original_dataset!$J$2:$J$321),original_dataset!J8) -> 0.2 | K8: =original_dataset!K8 -> 1 | L8: =IF(ISBLANK(original_dataset!L8),MEDIAN(original_dataset!$L$2:$L$321),original_dataset!L8) -> 4.1 | M8: =original_dataset!M8 -> 806615.54 | N8: =original_dataset!N8 -> 131364.62 | O8: =IF(ISBLANK(original_dataset!J8),"Yes","No") -> No | P8: =IF(ISBLANK(original_dataset!L8),"Yes","No") -> No
A9: =original_dataset!A9 -> STR-1002 | B9: =original_dataset!B9 -> 2025-04-01 | C9: =original_dataset!C9 -> East | D9: =original_dataset!D9 -> High Street | E9: =original_dataset!E9 -> 68148.52 | F9: =original_dataset!F9 -> 8567 | G9: =original_dataset!G9 -> 0.127 | H9: =original_dataset!H9 -> 23 | I9: =original_dataset!I9 -> 95.6 | J9: =IF(ISBLANK(original_dataset!J9),MEDIAN(original_dataset!$J$2:$J$321),original_dataset!J9) -> 0.8 | K9: =original_dataset!K9 -> 0 | L9: =IF(ISBLANK(original_dataset!L9),MEDIAN(original_dataset!$L$2:$L$321),original_dataset!L9) -> 3.9 | M9: =original_dataset!M9 -> 850164.26 | N9: =original_dataset!N9 -> 149262.75 | O9: =IF(ISBLANK(original_dataset!J9),"Yes","No") -> No | P9: =IF(ISBLANK(original_dataset!L9),"Yes","No") -> No
A10: =original_dataset!A10 -> STR-1003 | B10: =original_dataset!B10 -> 2025-01-01 | C10: =original_dataset!C10 -> North | D10: =original_dataset!D10 -> Airport | E10: =original_dataset!E10 -> 71838.86 | F10: =original_dataset!F10 -> 10979 | G10: =original_dataset!G10 -> 0.215 | H10: =original_dataset!H10 -> 26 | I10: =original_dataset!I10 -> 88.6 | J10: =IF(ISBLANK(original_dataset!J10),MEDIAN(original_dataset!$J$2:$J$321),original_dataset!J10) -> 7.7 | K10: =original_dataset!K10 -> 1 | L10: =IF(ISBLANK(original_dataset!L10),MEDIAN(original_dataset!$L$2:$L$321),original_dataset!L10) -> 3.8 | M10: =original_dataset!M10 -> 930581.7 | N10: =original_dataset!N10 -> 136207.98 | O10: =IF(ISBLANK(original_dataset!J10),"Yes","No") -> No | P10: =IF(ISBLANK(original_dataset!L10),"Yes","No") -> No
A11: =original_dataset!A11 -> STR-1003 | B11: =original_dataset!B11 -> 2025-02-01 | C11: =original_dataset!C11 -> North | D11: =original_dataset!D11 -> Airport | E11: =original_dataset!E11 -> 68133.44 | F11: =original_dataset!F11 -> 9459 | G11: =original_dataset!G11 -> 0.22 | H11: =original_dataset!H11 -> 21 | I11: =original_dataset!I11 -> 85 | J11: =IF(ISBLANK(original_dataset!J11),MEDIAN(original_dataset!$J$2:$J$321),original_dataset!J11) -> 1.91 | K11: =original_dataset!K11 -> 0 | L11: =IF(ISBLANK(original_dataset!L11),MEDIAN(original_dataset!$L$2:$L$321),original_dataset!L11) -> 4.2 | M11: =original_dataset!M11 -> 779010.94 | N11: =original_dataset!N11 -> 106328.09 | O11: =IF(ISBLANK(original_dataset!J11),"Yes","No") -> No | P11: =IF(ISBLANK(original_dataset!L11),"Yes","No") -> No
A12: =original_dataset!A12 -> STR-1003 | B12: =original_dataset!B12 -> 2025-03-01 | C12: =original_dataset!C12 -> North | D12: =original_dataset!D12 -> Airport | E12: =original_dataset!E12 -> 34285.21 | F12: =original_dataset!F12 -> 9172 | G12: =original_dataset!G12 -> 0.213 | H12: =original_dataset!H12 -> 22 | I12: =original_dataset!I12 -> 88.3 | J12: =IF(ISBLANK(original_dataset!J12),MEDIAN(original_dataset!$J$2:$J$321),original_dataset!J12) -> 10.46 | K12: =original_dataset!K12 -> 1 | L12: =IF(ISBLANK(original_dataset!L12),MEDIAN(original_dataset!$L$2:$L$321),original_dataset!L12) -> 3.8 | M12: =original_dataset!M12 -> 723060.76 | N12: =original_dataset!N12 -> 123131.24 | O12: =IF(ISBLANK(original_dataset!J12),"Yes","No") -> No | P12: =IF(ISBLANK(original_dataset!L12),"Yes","No") -> No
A13: =original_dataset!A13 -> STR-1003 | B13: =original_dataset!B13 -> 2025-04-01 | C13: =original_dataset!C13 -> North | D13: =original_dataset!D13 -> Airport | E13: =original_dataset!E13 -> 67979.88 | F13: =original_dataset!F13 -> 11230 | G13: =original_dataset!G13 -> 0.002 | H13: =original_dataset!H13 -> 28 | I13: =original_dataset!I13 -> 85.3 | J13: =IF(ISBLANK(original_dataset!J13),MEDIAN(original_dataset!$J$2:$J$321),original_dataset!J13) -> 7.16 | K13: =original_dataset!K13 -> 0 | L13: =IF(ISBLANK(original_dataset!L13),MEDIAN(original_dataset!$L$2:$L$321),original_dataset!L13) -> 3.8 | M13: =original_dataset!M13 -> 910791.94 | N13: =original_dataset!N13 -> 158891.28 | O13: =IF(ISBLANK(original_dataset!J13),"Yes","No") -> No | P13: =IF(ISBLANK(original_dataset!L13),"Yes","No") -> No
... A321: =original_dataset!A321 -> STR-1080 | B321: =original_dataset!B321 -> 2025-04-01 | C321: =original_dataset!C321 -> East | D321: =original_dataset!D321 -> Residential | E321: =original_dataset!E321 -> 40553.11 | F321: =original_dataset!F321 -> 5317 | G321: =original_dataset!G321 -> 0.165 | H321: =original_dataset!H321 -> 17 | I321: =original_dataset!I321 -> 84.3 | J321: =IF(ISBLANK(original_dataset!J321),MEDIAN(original_dataset!$J$2:$J$321),original_dataset!J321) -> 11.82 | K321: =original_dataset!K321 -> 0 | L321: =IF(ISBLANK(original_dataset!L321),MEDIAN(original_dataset!$L$2:$L$321),original_dataset!L321) -> 4.1 | M321: =original_dataset!M321 -> 559660.84 | N321: =original_dataset!N321 -> 71443.61 | O321: =IF(ISBLANK(original_dataset!J321),"Yes","No") -> No | P321: =IF(ISBLANK(original_dataset!L321),"Yes","No") -> No
A323: Note: competitor_distance_km and customer_rating had missing values (6 and 8 records respectively), imputed using column median. All other fields copied directly from original_dataset.

Sheet dummy_variables
A1: store_id | B1: month | C1: region | D1: store_type | E1: marketing_spend | F1: footfall | G1: avg_discount_pct | H1: staff_count | I1: inventory_availability_pct | J1: competitor_distance_km | K1: holiday_flag | L1: customer_rating | M1: monthly_sales | N1: monthly_profit | O1: region_North | P1: region_South | Q1: region_West | R1: store_Airport | S1: store_Mall | T1: store_Residential
A2: =cleaned_data!A2 -> STR-1001 | B2: =cleaned_data!B2 -> 2025-01-01 | C2: =cleaned_data!C2 -> East | D2: =cleaned_data!D2 -> Residential | E2: =cleaned_data!E2 -> 70389.11 | F2: =cleaned_data!F2 -> 8302 | G2: =cleaned_data!G2 -> 0.042 | H2: =cleaned_data!H2 -> 17 | ... N2: =cleaned_data!N2 -> 84349.93 | O2: =IF(cleaned_data!C2="North",1,0) -> 0 | P2: =IF(cleaned_data!C2="South",1,0) -> 0 | Q2: =IF(cleaned_data!C2="West",1,0) -> 0 | R2: =IF(cleaned_data!D2="Airport",1,0) -> 0 | S2: =IF(cleaned_data!D2="Mall",1,0) -> 0 | T2: =IF(cleaned_data!D2="Residential",1,0) -> 1
A3: =cleaned_data!A3 -> STR-1001 | B3: =cleaned_data!B3 -> 2025-02-01 | C3: =cleaned_data!C3 -> East | D3: =cleaned_data!D3 -> Residential | E3: =cleaned_data!E3 -> 43827.89 | F3: =cleaned_data!F3 -> 8487 | G3: =cleaned_data!G3 -> 0.168 | H3: =cleaned_data!H3 -> 23 | ... N3: =cleaned_data!N3 -> 106130.54 | O3: =IF(cleaned_data!C3="North",1,0) -> 0 | P3: =IF(cleaned_data!C3="South",1,0) -> 0 | Q3: =IF(cleaned_data!C3="West",1,0) -> 0 | R3: =IF(cleaned_data!D3="Airport",1,0) -> 0 | S3: =IF(cleaned_data!D3="Mall",1,0) -> 0 | T3: =IF(cleaned_data!D3="Residential",1,0) -> 1
A4: =cleaned_data!A4 -> STR-1001 | B4: =cleaned_data!B4 -> 2025-03-01 | C4: =cleaned_data!C4 -> East | D4: =cleaned_data!D4 -> Residential | E4: =cleaned_data!E4 -> 59921.75 | F4: =cleaned_data!F4 -> 9113 | G4: =cleaned_data!G4 -> 0.133 | H4: =cleaned_data!H4 -> 20 | ... N4: =cleaned_data!N4 -> 101883.86 | O4: =IF(cleaned_data!C4="North",1,0) -> 0 | P4: =IF(cleaned_data!C4="South",1,0) -> 0 | Q4: =IF(cleaned_data!C4="West",1,0) -> 0 | R4: =IF(cleaned_data!D4="Airport",1,0) -> 0 | S4: =IF(cleaned_data!D4="Mall",1,0) -> 0 | T4: =IF(cleaned_data!D4="Residential",1,0) -> 1
A5: =cleaned_data!A5 -> STR-1001 | B5: =cleaned_data!B5 -> 2025-04-01 | C5: =cleaned_data!C5 -> East | D5: =cleaned_data!D5 -> Residential | E5: =cleaned_data!E5 -> 56856.63 | F5: =cleaned_data!F5 -> 9431 | G5: =cleaned_data!G5 -> 0.142 | H5: =cleaned_data!H5 -> 23 | ... N5: =cleaned_data!N5 -> 97910.37 | O5: =IF(cleaned_data!C5="North",1,0) -> 0 | P5: =IF(cleaned_data!C5="South",1,0) -> 0 | Q5: =IF(cleaned_data!C5="West",1,0) -> 0 | R5: =IF(cleaned_data!D5="Airport",1,0) -> 0 | S5: =IF(cleaned_data!D5="Mall",1,0) -> 0 | T5: =IF(cleaned_data!D5="Residential",1,0) -> 1
A6: =cleaned_data!A6 -> STR-1002 | B6: =cleaned_data!B6 -> 2025-01-01 | C6: =cleaned_data!C6 -> East | D6: =cleaned_data!D6 -> High Street | E6: =cleaned_data!E6 -> 48412.64 | F6: =cleaned_data!F6 -> 9545 | G6: =cleaned_data!G6 -> 0.231 | H6: =cleaned_data!H6 -> 21 | ... N6: =cleaned_data!N6 -> 119208.17 | O6: =IF(cleaned_data!C6="North",1,0) -> 0 | P6: =IF(cleaned_data!C6="South",1,0) -> 0 | Q6: =IF(cleaned_data!C6="West",1,0) -> 0 | R6: =IF(cleaned_data!D6="Airport",1,0) -> 0 | S6: =IF(cleaned_data!D6="Mall",1,0) -> 0 | T6: =IF(cleaned_data!D6="Residential",1,0) -> 0
A7: =cleaned_data!A7 -> STR-1002 | B7: =cleaned_data!B7 -> 2025-02-01 | C7: =cleaned_data!C7 -> East | D7: =cleaned_data!D7 -> High Street | E7: =cleaned_data!E7 -> 64811.21 | F7: =cleaned_data!F7 -> 9792 | G7: =cleaned_data!G7 -> 0.112 | H7: =cleaned_data!H7 -> 20 | ... N7: =cleaned_data!N7 -> 149602.23 | O7: =IF(cleaned_data!C7="North",1,0) -> 0 | P7: =IF(cleaned_data!C7="South",1,0) -> 0 | Q7: =IF(cleaned_data!C7="West",1,0) -> 0 | R7: =IF(cleaned_data!D7="Airport",1,0) -> 0 | S7: =IF(cleaned_data!D7="Mall",1,0) -> 0 | T7: =IF(cleaned_data!D7="Residential",1,0) -> 0
A8: =cleaned_data!A8 -> STR-1002 | B8: =cleaned_data!B8 -> 2025-03-01 | C8: =cleaned_data!C8 -> East | D8: =cleaned_data!D8 -> High Street | E8: =cleaned_data!E8 -> 46213.45 | F8: =cleaned_data!F8 -> 10616 | G8: =cleaned_data!G8 -> 0.122 | H8: =cleaned_data!H8 -> 22 | ... N8: =cleaned_data!N8 -> 131364.62 | O8: =IF(cleaned_data!C8="North",1,0) -> 0 | P8: =IF(cleaned_data!C8="South",1,0) -> 0 | Q8: =IF(cleaned_data!C8="West",1,0) -> 0 | R8: =IF(cleaned_data!D8="Airport",1,0) -> 0 | S8: =IF(cleaned_data!D8="Mall",1,0) -> 0 | T8: =IF(cleaned_data!D8="Residential",1,0) -> 0
A9: =cleaned_data!A9 -> STR-1002 | B9: =cleaned_data!B9 -> 2025-04-01 | C9: =cleaned_data!C9 -> East | D9: =cleaned_data!D9 -> High Street | E9: =cleaned_data!E9 -> 68148.52 | F9: =cleaned_data!F9 -> 8567 | G9: =cleaned_data!G9 -> 0.127 | H9: =cleaned_data!H9 -> 23 | ... N9: =cleaned_data!N9 -> 149262.75 | O9: =IF(cleaned_data!C9="North",1,0) -> 0 | P9: =IF(cleaned_data!C9="South",1,0) -> 0 | Q9: =IF(cleaned_data!C9="West",1,0) -> 0 | R9: =IF(cleaned_data!D9="Airport",1,0) -> 0 | S9: =IF(cleaned_data!D9="Mall",1,0) -> 0 | T9: =IF(cleaned_data!D9="Residential",1,0) -> 0
A10: =cleaned_data!A10 -> STR-1003 | B10: =cleaned_data!B10 -> 2025-01-01 | C10: =cleaned_data!C10 -> North | D10: =cleaned_data!D10 -> Airport | E10: =cleaned_data!E10 -> 71838.86 | F10: =cleaned_data!F10 -> 10979 | G10: =cleaned_data!G10 -> 0.215 | H10: =cleaned_data!H10 -> 26 | ... N10: =cleaned_data!N10 -> 136207.98 | O10: =IF(cleaned_data!C10="North",1,0) -> 1 | P10: =IF(cleaned_data!C10="South",1,0) -> 0 | Q10: =IF(cleaned_data!C10="West",1,0) -> 0 | R10: =IF(cleaned_data!D10="Airport",1,0) -> 1 | S10: =IF(cleaned_data!D10="Mall",1,0) -> 0 | T10: =IF(cleaned_data!D10="Residential",1,0) -> 0
A11: =cleaned_data!A11 -> STR-1003 | B11: =cleaned_data!B11 -> 2025-02-01 | C11: =cleaned_data!C11 -> North | D11: =cleaned_data!D11 -> Airport | E11: =cleaned_data!E11 -> 68133.44 | F11: =cleaned_data!F11 -> 9459 | G11: =cleaned_data!G11 -> 0.22 | H11: =cleaned_data!H11 -> 21 | ... N11: =cleaned_data!N11 -> 106328.09 | O11: =IF(cleaned_data!C11="North",1,0) -> 1 | P11: =IF(cleaned_data!C11="South",1,0) -> 0 | Q11: =IF(cleaned_data!C11="West",1,0) -> 0 | R11: =IF(cleaned_data!D11="Airport",1,0) -> 1 | S11: =IF(cleaned_data!D11="Mall",1,0) -> 0 | T11: =IF(cleaned_data!D11="Residential",1,0) -> 0
A12: =cleaned_data!A12 -> STR-1003 | B12: =cleaned_data!B12 -> 2025-03-01 | C12: =cleaned_data!C12 -> North | D12: =cleaned_data!D12 -> Airport | E12: =cleaned_data!E12 -> 34285.21 | F12: =cleaned_data!F12 -> 9172 | G12: =cleaned_data!G12 -> 0.213 | H12: =cleaned_data!H12 -> 22 | ... N12: =cleaned_data!N12 -> 123131.24 | O12: =IF(cleaned_data!C12="North",1,0) -> 1 | P12: =IF(cleaned_data!C12="South",1,0) -> 0 | Q12: =IF(cleaned_data!C12="West",1,0) -> 0 | R12: =IF(cleaned_data!D12="Airport",1,0) -> 1 | S12: =IF(cleaned_data!D12="Mall",1,0) -> 0 | T12: =IF(cleaned_data!D12="Residential",1,0) -> 0
A13: =cleaned_data!A13 -> STR-1003 | B13: =cleaned_data!B13 -> 2025-04-01 | C13: =cleaned_data!C13 -> North | D13: =cleaned_data!D13 -> Airport | E13: =cleaned_data!E13 -> 67979.88 | F13: =cleaned_data!F13 -> 11230 | G13: =cleaned_data!G13 -> 0.002 | H13: =cleaned_data!H13 -> 28 | ... N13: =cleaned_data!N13 -> 158891.28 | O13: =IF(cleaned_data!C13="North",1,0) -> 1 | P13: =IF(cleaned_data!C13="South",1,0) -> 0 | Q13: =IF(cleaned_data!C13="West",1,0) -> 0 | R13: =IF(cleaned_data!D13="Airport",1,0) -> 1 | S13: =IF(cleaned_data!D13="Mall",1,0) -> 0 | T13: =IF(cleaned_data!D13="Residential",1,0) -> 0
... A321: =cleaned_data!A321 -> STR-1080 | B321: =cleaned_data!B321 -> 2025-04-01 | C321: =cleaned_data!C321 -> East | D321: =cleaned_data!D321 -> Residential | E321: =cleaned_data!E321 -> 40553.11 | F321: =cleaned_data!F321 -> 5317 | G321: =cleaned_data!G321 -> 0.165 | H321: =cleaned_data!H321 -> 17 | ... N321: =cleaned_data!N321 -> 71443.61 | O321: =IF(cleaned_data!C321="North",1,0) -> 0 | P321: =IF(cleaned_data!C321="South",1,0) -> 0 | Q321: =IF(cleaned_data!C321="West",1,0) -> 0 | R321: =IF(cleaned_data!D321="Airport",1,0) -> 0 | S321: =IF(cleaned_data!D321="Mall",1,0) -> 0 | T321: =IF(cleaned_data!D321="Residential",1,0) -> 1
A323: Reference categories (dropped to avoid dummy-variable trap): region = East, store_type = High Street. Both are the most frequent category, so all dummy coefficients are interpreted relative to a typical East / High Street store.

Sheet simple_regression
A1: TASK 4: SIMPLE LINEAR REGRESSION MODELS (Dependent variable: monthly_sales)
A3: Model: monthly_sales ~ footfall
A4: Intercept (b0) | B4: =INTERCEPT(cleaned_data!$M$2:$M$321,cleaned_data!$F$2:$F$321) -> 446410.58
A5: Slope / Coefficient (b1) | B5: =SLOPE(cleaned_data!$M$2:$M$321,cleaned_data!$F$2:$F$321) -> 35.678031
A6: R-squared | B6: =RSQ(cleaned_data!$M$2:$M$321,cleaned_data!$F$2:$F$321) -> 0.73628534
A7: Std. Error of slope | B7: =SQRT((DEVSQ(cleaned_data!$M$2:$M$321)*(1-B6))/(COUNT(cleaned_data!$F$2:$F$321)-2)/DEVSQ(cleaned_data!$F$2:$F$321)) -> 1.1973783
A8: t-statistic | B8: =B5/B7 -> 29.796791
A9: p-value | B9: =_xlfn.T.DIST.2T(ABS(B8),COUNT(cleaned_data!$F$2:$F$321)-2) -> 4.7503615e-94
A10: n (observations) | B10: =COUNT(cleaned_data!$F$2:$F$321) -> 320
A11: Statistically significant? (p<0.05) | B11: =IF(B9<0.05,"Yes - significant","No - not significant") -> Yes - significant
A12: Equation | B12: ="monthly_sales = "&ROUND(B4,2)&" + "&ROUND(B5,4)&" * footfall" -> monthly_sales = 446410.58 + 35.678 * footfall
A13: Business note | B13: Foot traffic is by far the strongest single driver of sales in this dataset.
A15: Model: monthly_sales ~ marketing_spend
A16: Intercept (b0) | B16: =INTERCEPT(cleaned_data!$M$2:$M$321,cleaned_data!$E$2:$E$321) -> 560777.35
A17: Slope / Coefficient (b1) | B17: =SLOPE(cleaned_data!$M$2:$M$321,cleaned_data!$E$2:$E$321) -> 2.1295753
A18: R-squared | B18: =RSQ(cleaned_data!$M$2:$M$321,cleaned_data!$E$2:$E$321) -> 0.16724469
A19: Std. Error of slope | B19: =SQRT((DEVSQ(cleaned_data!$M$2:$M$321)*(1-B18))/(COUNT(cleaned_data!$E$2:$E$321)-2)/DEVSQ(cleaned_data!$E$2:$E$321)) -> 0.26647838
A20: t-statistic | B20: =B17/B19 -> 7.9915501
A21: p-value | B21: =_xlfn.T.DIST.2T(ABS(B20),COUNT(cleaned_data!$E$2:$E$321)-2) -> 2.4800615e-14
A22: n (observations) | B22: =COUNT(cleaned_data!$E$2:$E$321) -> 320
A23: Statistically significant? (p<0.05) | B23: =IF(B21<0.05,"Yes - significant","No - not significant") -> Yes - significant
A24: Equation | B24: ="monthly_sales = "&ROUND(B16,2)&" + "&ROUND(B17,4)&" * marketing_spend" -> monthly_sales = 560777.35 + 2.1296 * marketing_spend
A25: Business note | B25: Marketing spend shows a real but modest standalone link to sales.
A27: Model: monthly_sales ~ inventory_availability_pct
A28: Intercept (b0) | B28: =INTERCEPT(cleaned_data!$M$2:$M$321,cleaned_data!$I$2:$I$321) -> 484814.26
A29: Slope / Coefficient (b1) | B29: =SLOPE(cleaned_data!$M$2:$M$321,cleaned_data!$I$2:$I$321) -> 2217.8319
A30: R-squared | B30: =RSQ(cleaned_data!$M$2:$M$321,cleaned_data!$I$2:$I$321) -> 0.013115016
A31: Std. Error of slope | B31: =SQRT((DEVSQ(cleaned_data!$M$2:$M$321)*(1-B30))/(COUNT(cleaned_data!$I$2:$I$321)-2)/DEVSQ(cleaned_data!$I$2:$I$321)) -> 1078.8571
A32: t-statistic | B32: =B29/B31 -> 2.0557235
A33: p-value | B33: =_xlfn.T.DIST.2T(ABS(B32),COUNT(cleaned_data!$I$2:$I$321)-2) -> 0.040625297
A34: n (observations) | B34: =COUNT(cleaned_data!$I$2:$I$321) -> 320
A35: Statistically significant? (p<0.05) | B35: =IF(B33<0.05,"Yes - significant","No - not significant") -> Yes - significant
A36: Equation | B36: ="monthly_sales = "&ROUND(B28,2)&" + "&ROUND(B29,4)&" * inventory_availability_pct" -> monthly_sales = 484814.26 + 2217.8319 * inventory_availability_pct
A37: Business note | B37: Keeping products in stock is linked to higher sales, though the effect is small in isolation.
A39: Model: monthly_sales ~ avg_discount_pct
A40: Intercept (b0) | B40: =INTERCEPT(cleaned_data!$M$2:$M$321,cleaned_data!$G$2:$G$321) -> 697835.63
A41: Slope / Coefficient (b1) | B41: =SLOPE(cleaned_data!$M$2:$M$321,cleaned_data!$G$2:$G$321) -> -138730.45
A42: R-squared | B42: =RSQ(cleaned_data!$M$2:$M$321,cleaned_data!$G$2:$G$321) -> 0.008290503
A43: Std. Error of slope | B43: =SQRT((DEVSQ(cleaned_data!$M$2:$M$321)*(1-B42))/(COUNT(cleaned_data!$G$2:$G$321)-2)/DEVSQ(cleaned_data!$G$2:$G$321)) -> 85086.38
A44: t-statistic | B44: =B41/B43 -> -1.6304661
...

Sheet multiple_regression
A1: TASK 5: MULTIPLE REGRESSION MODEL (Final model) — Dependent variable: monthly_sales
A3: --- Staging data block (live references to dummy_variables sheet; used by LINEST below) ---
A4: marketing_spend | B4: footfall | C4: avg_discount_pct | D4: inventory_availability_pct | E4: competitor_distance_km | F4: holiday_flag | G4: customer_rating | H4: region_North | I4: region_South | J4: region_West | K4: store_Airport | L4: store_Mall | M4: store_Residential | N4: monthly_sales | Q4: Term | R4: Coefficient | S4: Std Error | T4: t-stat | U4: p-value | V4: Significant (p<0.05)
A5: =dummy_variables!E2 -> 70389.11 | B5: =dummy_variables!F2 -> 8302 | C5: =dummy_variables!G2 -> 0.042 | D5: =dummy_variables!I2 -> 75 | E5: =dummy_variables!J2 -> 5.28 | F5: =dummy_variables!K2 -> 1 | G5: =dummy_variables!L2 -> 3.1 | H5: =dummy_variables!O2 -> 0 | I5: =dummy_variables!P2 -> 0 | J5: =dummy_variables!Q2 -> 0 | K5: =dummy_variables!R2 -> 0 | L5: =dummy_variables!S2 -> 0 | M5: =dummy_variables!T2 -> 1 | N5: =dummy_variables!M2 -> 658832.62 | Q5: Intercept | R5: =INDEX(LINEST($N$5:$N$324,$A$5:$M$324,TRUE(),TRUE()),1,14) -> 83220.58 | S5: =INDEX(LINEST($N$5:$N$324,$A$5:$M$324,TRUE(),TRUE()),2,14) -> 44883.669 | T5: =R5/S5 -> 1.8541394 | U5: =_xlfn.T.DIST.2T(ABS(T5),R23) -> 0.06468128 | V5: =IF(U5<0.05,"Yes","No") -> No
A6: =dummy_variables!E3 -> 43827.89 | B6: =dummy_variables!F3 -> 8487 | C6: =dummy_variables!G3 -> 0.168 | D6: =dummy_variables!I3 -> 84.4 | E6: =dummy_variables!J3 -> 4.31 | F6: =dummy_variables!K3 -> 0 | G6: =dummy_variables!L3 -> 2.8 | H6: =dummy_variables!O3 -> 0 | I6: =dummy_variables!P3 -> 0 | J6: =dummy_variables!Q3 -> 0 | K6: =dummy_variables!R3 -> 0 | L6: =dummy_variables!S3 -> 0 | M6: =dummy_variables!T3 -> 1 | N6: =dummy_variables!M3 -> 634436 | Q6: marketing_spend | R6: =INDEX(LINEST($N$5:$N$324,$A$5:$M$324,TRUE(),TRUE()),1,13) -> 1.2280521 | S6: =INDEX(LINEST($N$5:$N$324,$A$5:$M$324,TRUE(),TRUE()),2,13) -> 0.11832428 | T6: =R6/S6 -> 10.378699 | U6: =_xlfn.T.DIST.2T(ABS(T6),R23) -> 8.0670758e-22 | V6: =IF(U6<0.05,"Yes","No") -> Yes
A7: =dummy_variables!E4 -> 59921.75 | B7: =dummy_variables!F4 -> 9113 | C7: =dummy_variables!G4 -> 0.133 | D7: =dummy_variables!I4 -> 88 | E7: =dummy_variables!J4 -> 12 | F7: =dummy_variables!K4 -> 0 | G7: =dummy_variables!L4 -> 3.2 | H7: =dummy_variables!O4 -> 0 | I7: =dummy_variables!P4 -> 0 | J7: =dummy_variables!Q4 -> 0 | K7: =dummy_variables!R4 -> 0 | L7: =dummy_variables!S4 -> 0 | M7: =dummy_variables!T4 -> 1 | N7: =dummy_variables!M4 -> 678722.06 | Q7: footfall | R7: =INDEX(LINEST($N$5:$N$324,$A$5:$M$324,TRUE(),TRUE()),1,12) -> 33.678713 | S7: =INDEX(LINEST($N$5:$N$324,$A$5:$M$324,TRUE(),TRUE()),2,12) -> 0.96541026 | T7: =R7/S7 -> 34.88539 | U7: =_xlfn.T.DIST.2T(ABS(T7),R23) -> 1.1743214e-108 | V7: =IF(U7<0.05,"Yes","No") -> Yes
A8: =dummy_variables!E5 -> 56856.63 | B8: =dummy_variables!F5 -> 9431 | C8: =dummy_variables!G5 -> 0.142 | D8: =dummy_variables!I5 -> 86.9 | E8: =dummy_variables!J5 -> 4.97 | F8: =dummy_variables!K5 -> 0 | G8: =dummy_variables!L5 -> 3.4 | H8: =dummy_variables!O5 -> 0 | I8: =dummy_variables!P5 -> 0 | J8: =dummy_variables!Q5 -> 0 | K8: =dummy_variables!R5 -> 0 | L8: =dummy_variables!S5 -> 0 | M8: =dummy_variables!T5 -> 1 | N8: =dummy_variables!M5 -> 658920.3 | Q8: avg_discount_pct | R8: =INDEX(LINEST($N$5:$N$324,$A$5:$M$324,TRUE(),TRUE()),1,11) -> -37239.952 | S8: =INDEX(LINEST($N$5:$N$324,$A$5:$M$324,TRUE(),TRUE()),2,11) -> 34296.152 | T8: =R8/S8 -> -1.0858347 | U8: =_xlfn.T.DIST.2T(ABS(T8),R23) -> 0.27840678 | V8: =IF(U8<0.05,"Yes","No") -> No
A9: =dummy_variables!E6 -> 48412.64 | B9: =dummy_variables!F6 -> 9545 | C9: =dummy_variables!G6 -> 0.231 | D9: =dummy_variables!I6 -> 97.6 | E9: =dummy_variables!J6 -> 6.94 | F9: =dummy_variables!K6 -> 1 | G9: =dummy_variables!L6 -> 4.2 | H9: =dummy_variables!O6 -> 0 | I9: =dummy_variables!P6 -> 0 | J9: =dummy_variables!Q6 -> 0 | K9: =dummy_variables!R6 -> 0 | L9: =dummy_variables!S6 -> 0 | M9: =dummy_variables!T6 -> 0 | N9: =dummy_variables!M6 -> 741341.44 | Q9: inventory_availability_pct | R9: =INDEX(LINEST($N$5:$N$324,$A$5:$M$324,TRUE(),TRUE()),1,10) -> 3006.1847 | S9: =INDEX(LINEST($N$5:$N$324,$A$5:$M$324,TRUE(),TRUE()),2,10) -> 431.30914 | T9: =R9/S9 -> 6.9699071 | U9: =_xlfn.T.DIST.2T(ABS(T9),R23) -> 1.9546008e-11 | V9: =IF(U9<0.05,"Yes","No") -> Yes
A10: =dummy_variables!E7 -> 64811.21 | B10: =dummy_variables!F7 -> 9792 | C10: =dummy_variables!G7 -> 0.112 | D10: =dummy_variables!I7 -> 84.2 | E10: =dummy_variables!J7 -> 2.88 | F10: =dummy_variables!K7 -> 0 | G10: =dummy_variables!L7 -> 4.2 | H10: =dummy_variables!O7 -> 0 | I10: =dummy_variables!P7 -> 0 | J10: =dummy_variables!Q7 -> 0 | K10: =dummy_variables!R7 -> 0 | L10: =dummy_variables!S7 -> 0 | M10: =dummy_variables!T7 -> 0 | N10: =dummy_variables!M7 -> 761835.34 | Q10: competitor_distance_km | R10: =INDEX(LINEST($N$5:$N$324,$A$5:$M$324,TRUE(),TRUE()),1,9) -> -3367.3427 | S10: =INDEX(LINEST($N$5:$N$324,$A$5:$M$324,TRUE(),TRUE()),2,9) -> 546.88556 | T10: =R10/S10 -> -6.1573078 | U10: =_xlfn.T.DIST.2T(ABS(T10),R23) -> 2.3210707e-09 | V10: =IF(U10<0.05,"Yes","No") -> Yes
A11: =dummy_variables!E8 -> 46213.45 | B11: =dummy_variables!F8 -> 10616 | C11: =dummy_variables!G8 -> 0.122 | D11: =dummy_variables!I8 -> 85.2 | E11: =dummy_variables!J8 -> 0.2 | F11: =dummy_variables!K8 -> 1 | G11: =dummy_variables!L8 -> 4.1 | H11: =dummy_variables!O8 -> 0 | I11: =dummy_variables!P8 -> 0 | J11: =dummy_variables!Q8 -> 0 | K11: =dummy_variables!R8 -> 0 | L11: =dummy_variables!S8 -> 0 | M11: =dummy_variables!T8 -> 0 | N11: =dummy_variables!M8 -> 806615.54 | Q11: holiday_flag | R11: =INDEX(LINEST($N$5:$N$324,$A$5:$M$324,TRUE(),TRUE()),1,8) -> 14176.089 | S11: =INDEX(LINEST($N$5:$N$324,$A$5:$M$324,TRUE(),TRUE()),2,8) -> 6199.837 | T11: =R11/S11 -> 2.286526 | U11: =_xlfn.T.DIST.2T(ABS(T11),R23) -> 0.022906414 | V11: =IF(U11<0.05,"Yes","No") -> Yes
A12: =dummy_variables!E9 -> 68148.52 | B12: =dummy_variables!F9 -> 8567 | C12: =dummy_variables!G9 -> 0.127 | D12: =dummy_variables!I9 -> 95.6 | E12: =dummy_variables!J9 -> 0.8 | F12: =dummy_variables!K9 -> 0 | G12: =dummy_variables!L9 -> 3.9 | H12: =dummy_variables!O9 -> 0 | I12: =dummy_variables!P9 -> 0 | J12: =dummy_variables!Q9 -> 0 | K12: =dummy_variables!R9 -> 0 | L12: =dummy_variables!S9 -> 0 | M12: =dummy_variables!T9 -> 0 | N12: =dummy_variables!M9 -> 850164.26 | Q12: customer_rating | R12: =INDEX(LINEST($N$5:$N$324,$A$5:$M$324,TRUE(),TRUE()),1,7) -> 11907.944 | S12: =INDEX(LINEST($N$5:$N$324,$A$5:$M$324,TRUE(),TRUE()),2,7) -> 4502.9997 | T12: =R12/S12 -> 2.6444469 | U12: =_xlfn.T.DIST.2T(ABS(T12),R23) -> 0.0086045393 | V12: =IF(U12<0.05,"Yes","No") -> Yes
A13: =dummy_variables!E10 -> 71838.86 | B13: =dummy_variables!F10 -> 10979 | C13: =dummy_variables!G10 -> 0.215 | D13: =dummy_variables!I10 -> 88.6 | E13: =dummy_variables!J10 -> 7.7 | F13: =dummy_variables!K10 -> 1 | G13: =dummy_variables!L10 -> 3.8 | H13: =dummy_variables!O10 -> 1 | I13: =dummy_variables!P10 -> 0 | J13: =dummy_variables!Q10 -> 0 | K13: =dummy_variables!R10 -> 1 | L13: =dummy_variables!S10 -> 0 | M13: =dummy_variables!T10 -> 0 | N13: =dummy_variables!M10 -> 930581.7 | Q13: region_North | R13: =INDEX(LINEST($N$5:$N$324,$A$5:$M$324,TRUE(),TRUE()),1,6) -> 10896.371 | S13: =INDEX(LINEST($N$5:$N$324,$A$5:$M$324,TRUE(),TRUE()),2,6) -> 6646.2273 | T13: =R13/S13 -> 1.6394822 | U13: =_xlfn.T.DIST.2T(ABS(T13),R23) -> 0.1021405 | V13: =IF(U13<0.05,"Yes","No") -> No
A14: =dummy_variables!E11 -> 68133.44 | B14: =dummy_variables!F11 -> 9459 | C14: =dummy_variables!G11 -> 0.22 | D14: =dummy_variables!I11 -> 85 | E14: =dummy_variables!J11 -> 1.91 | F14: =dummy_variables!K11 -> 0 | G14: =dummy_variables!L11 -> 4.2 | H14: =dummy_variables!O11 -> 1 | I14: =dummy_variables!P11 -> 0 | J14: =dummy_variables!Q11 -> 0 | K14: =dummy_variables!R11 -> 1 | L14: =dummy_variables!S11 -> 0 | M14: =dummy_variables!T11 -> 0 | N14: =dummy_variables!M11 -> 779010.94 | Q14: region_South | R14: =INDEX(LINEST($N$5:$N$324,$A$5:$M$324,TRUE(),TRUE()),1,5) -> 20358.333 | S14: =INDEX(LINEST($N$5:$N$324,$A$5:$M$324,TRUE(),TRUE()),2,5) -> 6712.987 | T14: =R14/S14 -> 3.0326788 | U14: =_xlfn.T.DIST.2T(ABS(T14),R23) -> 0.0026314399 | V14: =IF(U14<0.05,"Yes","No") -> Yes
A15: =dummy_variables!E12 -> 34285.21 | B15: =dummy_variables!F12 -> 9172 | C15: =dummy_variables!G12 -> 0.213 | D15: =dummy_variables!I12 -> 88.3 | E15: =dummy_variables!J12 -> 10.46 | F15: =dummy_variables!K12 -> 1 | G15: =dummy_variables!L12 -> 3.8 | H15: =dummy_variables!O12 -> 1 | I15: =dummy_variables!P12 -> 0 | J15: =dummy_variables!Q12 -> 0 | K15: =dummy_variables!R12 -> 1 | L15: =dummy_variables!S12 -> 0 | M15: =dummy_variables!T12 -> 0 | N15: =dummy_variables!M12 -> 723060.76 | Q15: region_West | R15: =INDEX(LINEST($N$5:$N$324,$A$5:$M$324,TRUE(),TRUE()),1,4) -> 25193.395 | S15: =INDEX(LINEST($N$5:$N$324,$A$5:$M$324,TRUE(),TRUE()),2,4) -> 5976.4508 | T15: =R15/S15 -> 4.2154442 | U15: =_xlfn.T.DIST.2T(ABS(T15),R23) -> 3.2854755e-05 | V15: =IF(U15<0.05,"Yes","No") -> Yes
A16: =dummy_variables!E13 -> 67979.88 | B16: =dummy_variables!F13 -> 11230 | C16: =dummy_variables!G13 -> 0.002 | D16: =dummy_variables!I13 -> 85.3 | E16: =dummy_variables!J13 -> 7.16 | F16: =dummy_variables!K13 -> 0 | G16: =dummy_variables!L13 -> 3.8 | H16: =dummy_variables!O13 -> 1 | I16: =dummy_variables!P13 -> 0 | J16: =dummy_variables!Q13 -> 0 | K16: =dummy_variables!R13 -> 1 | L16: =dummy_variables!S13 -> 0 | M16: =dummy_variables!T13 -> 0 | N16: =dummy_variables!M13 -> 910791.94 | Q16: store_Airport | R16: =INDEX(LINEST($N$5:$N$324,$A$5:$M$324,TRUE(),TRUE()),1,3) -> 25124.014 | S16: =INDEX(LINEST($N$5:$N$324,$A$5:$M$324,TRUE(),TRUE()),2,3) -> 8725.6807 | T16: =R16/S16 -> 2.8793185 | U16: =_xlfn.T.DIST.2T(ABS(T16),R23) -> 0.0042663399 | V16: =IF(U16<0.05,"Yes","No") -> Yes
A17: =dummy_variables!E14 -> 71828.26 | B17: =dummy_variables!F14 -> 12775 | C17: =dummy_variables!G14 -> 0.116 | D17: =dummy_variables!I14 -> 81.7 | E17: =dummy_variables!J14 -> 4.24 | F17: =dummy_variables!K14 -> 1 | G17: =dummy_variables!L14 -> 4.2 | H17: =dummy_variables!O14 -> 0 | I17: =dummy_variables!P14 -> 0 | J17: =dummy_variables!Q14 -> 0 | K17: =dummy_variables!R14 -> 0 | L17: =dummy_variables!S14 -> 0 | M17: =dummy_variables!T14 -> 1 | N17: =dummy_variables!M14 -> 922168.6 | Q17: store_Mall | R17: =INDEX(LINEST($N$5:$N$324,$A$5:$M$324,TRUE(),TRUE()),1,2) -> 12780.927 | S17: =INDEX(LINEST($N$5:$N$324,$A$5:$M$324,TRUE(),TRUE()),2,2) -> 6101.2967 | T17: =R17/S17 -> 2.0947886 | U17: =_xlfn.T.DIST.2T(ABS(T17),R23) -> 0.037011808 | V17: =IF(U17<0.05,"Yes","No") -> Yes
A18: =dummy_variables!E15 -> 55716.82 | B18: =dummy_variables!F15 -> 10054 | C18: =dummy_variables!G15 -> 0.146 | D18: =dummy_variables!I15 -> 84.9 | E18: =dummy_variables!J15 -> 1.06 | F18: =dummy_variables!K15 -> 0 | G18: =dummy_variables!L15 -> 4.3 | H18: =dummy_variables!O15 -> 0 | I18: =dummy_variables!P15 -> 0 | J18: =dummy_variables!Q15 -> 0 | K18: =dummy_variables!R15 -> 0 | L18: =dummy_variables!S15 -> 0 | M18: =dummy_variables!T15 -> 1 | N18: =dummy_variables!M15 -> 726606.28 | Q18: store_Residential | R18: =INDEX(LINEST($N$5:$N$324,$A$5:$M$324,TRUE(),TRUE()),1,1) -> -19071.791 | S18: =INDEX(LINEST($N$5:$N$324,$A$5:$M$324,TRUE(),TRUE()),2,1) -> 5625.2186 | T18: =R18/S18 -> -3.3904089 | U18: =_xlfn.T.DIST.2T(ABS(T18),R23) -> 0.00078945484 | V18: =IF(U18<0.05,"Yes","No") -> Yes
A19: =dummy_variables!E16 -> 59909.51 | B19: =dummy_variables!F16 -> 8895 | C19: =dummy_variables!G16 -> 0.228 | D19: =dummy_variables!I16 -> 88.8 | E19: =dummy_variables!J16 -> 0.27 | F19: =dummy_variables!K16 -> 0 | G19: =dummy_variables!L16 -> 4.3 | H19: =dummy_variables!O16 -> 0 | I19: =dummy_variables!P16 -> 0 | J19: =dummy_variables!Q16 -> 0 | K19: =dummy_variables!R16 -> 0 | L19: =dummy_variables!S16 -> 0 | M19: =dummy_variables!T16 -> 1 | N19: =dummy_variables!M16 -> 746501.09
A20: =dummy_variables!E17 -> 75305.71 | B20: =dummy_variables!F17 -> 10940 | C20: =dummy_variables!G17 -> 0.006 | D20: =dummy_variables!I17 -> 76.5 | E20: =dummy_variables!J17 -> 1.32 | F20: =dummy_variables!K17 -> 0 | G20: =dummy_variables!L17 -> 4.5 | H20: =dummy_variables!O17 -> 0 | I20: =dummy_variables!P17 -> 0 | J20: =dummy_variables!Q17 -> 0 | K20: =dummy_variables!R17 -> 0 | L20: =dummy_variables!S17 -> 0 | M20: =dummy_variables!T17 -> 1 | N20: =dummy_variables!M17 -> 834017.02 | Q20: R-squared | R20: =INDEX(LINEST($N$5:$N$324,$A$5:$M$324,TRUE(),TRUE()),3,1) -> 0.85271151
A21: =dummy_variables!E18 -> 48804.22 | B21: =dummy_variables!F18 -> 7057 | C21: =dummy_variables!G18 -> 0.005 | D21: =dummy_variables!I18 -> 87.7 | E21: =dummy_variables!J18 -> 1.22 | F21: =dummy_variables!K18 -> 0 | G21: =dummy_variables!L18 -> 3.7 | H21: =dummy_variables!O18 -> 0 | I21: =dummy_variables!P18 -> 1 | J21: =dummy_variables!Q18 -> 0 | K21: =dummy_variables!R18 -> 0 | L21: =dummy_variables!S18 -> 0 | M21: =dummy_variables!T18 -> 1 | N21: =dummy_variables!M18 -> 666152.52 | Q21: Adjusted R-squared | R21: =1-(1-R20)*(COUNT($N$5:$N$324)-1)/(COUNT($N$5:$N$324)-13-1) -> 0.84645416
A22: =dummy_variables!E19 -> 59117.9 | B22: =dummy_variables!F19 -> 4263 | C22: =dummy_variables!G19 -> 0.119 | D22: =dummy_variables!I19 -> 87.6 | E22: =dummy_variables!J19 -> 4.01 | F22: =dummy_variables!K19 -> 0 | G22: =dummy_variables!L19 -> 3.6 | H22: =dummy_variables!O19 -> 0 | I22: =dummy_variables!P19 -> 1 | J22: =dummy_variables!Q19 -> 0 | K22: =dummy_variables!R19 -> 0 | L22: =dummy_variables!S19 -> 0 | M22: =dummy_variables!T19 -> 1 | N22: =dummy_variables!M19 -> 573155.19 | Q22: F-statistic | R22: =INDEX(LINEST($N$5:$N$324,$A$5:$M$324,TRUE(),TRUE()),4,1) -> 136.2735
A23: =dummy_variables!E20 -> 78831.12 | B23: =dummy_variables!F20 -> 5538 | C23: =dummy_variables!G20 -> 0 | D23: =dummy_variables!I20 -> 94.1 | E23: =dummy_variables!J20 -> 0.2 | F23: =dummy_variables!K20 -> 0 | G23: =dummy_variables!L20 -> 3.9 | H23: =dummy_variables!O20 -> 0 | I23: =dummy_variables!P20 -> 1 | J23: =dummy_variables!Q20 -> 0 | K23: =dummy_variables!R20 -> 0 | L23: =dummy_variables!S20 -> 0 | M23: =dummy_variables!T20 -> 1 | N23: =dummy_variables!M20 -> 666573.2 | Q23: df residual | R23: =INDEX(LINEST($N$5:$N$324,$A$5:$M$324,TRUE(),TRUE()),4,2) -> 306
A24: =dummy_variables!E21 -> 41441.93 | B24: =dummy_variables!F21 -> 4865 | C24: =dummy_variables!G21 -> 0.158 | D24: =dummy_variables!I21 -> 88.3 | E24: =dummy_variables!J21 -> 0.5 | F24: =dummy_variables!K21 -> 0 | G24: =dummy_variables!L21 -> 4 | H24: =dummy_variables!O21 -> 0 | I24: =dummy_variables!P21 -> 1 | J24: =dummy_variables!Q21 -> 0 | K24: =dummy_variables!R21 -> 0 | L24: =dummy_variables!S21 -> 0 | M24: =dummy_variables!T21 -> 1 | N24: =dummy_variables!M21 -> 591619.95 | Q24: n (observations) | R24: =COUNT($N$5:$N$324) -> 320
A25: =dummy_variables!E22 -> 30356.28 | B25: =dummy_variables!F22 -> 2822 | C25: =dummy_variables!G22 -> 0.231 | D25: =dummy_variables!I22 -> 84.8 | E25: =dummy_variables!J22 -> 6.95 | F25: =dummy_variables!K22 -> 0 | G25: =dummy_variables!L22 -> 5 | H25: =dummy_variables!O22 -> 1 | I25: =dummy_variables!P22 -> 0 | J25: =dummy_variables!Q22 -> 0 | K25: =dummy_variables!R22 -> 0 | L25: =dummy_variables!S22 -> 0 | M25: =dummy_variables!T22 -> 1 | N25: =dummy_variables!M22 -> 415721.82
A26: =dummy_variables!E23 -> 33518.88 | B26: =dummy_variables!F23 -> 2121 | C26: =dummy_variables!G23 -> 0.176 | D26: =dummy_variables!I23 -> 88.5 | E26: =dummy_variables!J23 -> 0.2 | F26: =dummy_variables!K23 -> 0 | G26: =dummy_variables!L23 -> 5 | H26: =dummy_variables!O23 -> 1 | I26: =dummy_variables!P23 -> 0 | J26: =dummy_variables!Q23 -> 0 | K26: =dummy_variables!R23 -> 0 | L26: =dummy_variables!S23 -> 0 | M26: =dummy_variables!T23 -> 1 | N26: =dummy_variables!M23 -> 491905.13
A27: =dummy_variables!E24 -> 42267.37 | B27: =dummy_variables!F24 -> 3364 | C27: =dummy_variables!G24 -> 0.16 | D27: =dummy_variables!I24 -> 82 | E27: =dummy_variables!J24 -> 1.61 | F27: =dummy_variables!K24 -> 1 | G27: =dummy_variables!L24 -> 4.6 | H27: =dummy_variables!O24 -> 1 | I27: =dummy_variables!P24 -> 0 | J27: =dummy_variables!Q24 -> 0 | K27: =dummy_variables!R24 -> 0 | L27: =dummy_variables!S24 -> 0 | M27: =dummy_variables!T24 -> 1 | N27: =dummy_variables!M24 -> 555929.4
A28: =dummy_variables!E25 -> 62060.43 | B28: =dummy_variables!F25 -> 2613 | C28: =dummy_variables!G25 -> 0.216 | D28: =dummy_variables!I25 -> 92.1 | E28: =dummy_variables!J25 -> 1.55 | F28: =dummy_variables!K25 -> 0 | G28: =dummy_variables!L25 -> 4.7 | H28: =dummy_variables!O25 -> 1 | I28: =dummy_variables!P25 -> 0 | J28: =dummy_variables!Q25 -> 0 | K28: =dummy_variables!R25 -> 0 | L28: =dummy_variables!S25 -> 0 | M28: =dummy_variables!T25 -> 1 | N28: =dummy_variables!M25 -> 565810.99
A29: =dummy_variables!E26 -> 57696.69 | B29: =dummy_variables!F26 -> 10218 | C29: =dummy_variables!G26 -> 0.121 | D29: =dummy_variables!I26 -> 94.8 | E29: =dummy_variables!J26 -> 2.99 | F29: =dummy_variables!K26 -> 0 | G29: =dummy_variables!L26 -> 3.5 | H29: =dummy_variables!O26 -> 0 | I29: =dummy_variables!P26 -> 0 | J29: =dummy_variables!Q26 -> 1 | K29: =dummy_variables!R26 -> 0 | L29: =dummy_variables!S26 -> 1 | M29: =dummy_variables!T26 -> 0 | N29: =dummy_variables!M26 -> 811771.14
A30: =dummy_variables!E27 -> 172415.52 | B30: =dummy_variables!F27 -> 8927 | C30: =dummy_variables!G27 -> 0.14 | D30: =dummy_variables!I27 -> 86.2 | E30: =dummy_variables!J27 -> 7.04 | F30: =dummy_variables!K27 -> 0 | G30: =dummy_variables!L27 -> 3.9 | H30: =dummy_variables!O27 -> 0 | I30: =dummy_variables!P27 -> 0 | J30: =dummy_variables!Q27 -> 1 | K30: =dummy_variables!R27 -> 0 | L30: =dummy_variables!S27 -> 1 | M30: =dummy_variables!T27 -> 0 | N30: =dummy_variables!M27 -> 800451.94
A31: =dummy_variables!E28 -> 55270.52 | B31: =dummy_variables!F28 -> 9315 | C31: =dummy_variables!G28 -> 0.169 | D31: =dummy_variables!I28 -> 91.9 | E31: =dummy_variables!J28 -> 4.94 | F31: =dummy_variables!K28 -> 0 | G31: =dummy_variables!L28 -> 4 | H31: =dummy_variables!O28 -> 0 | I31: =dummy_variables!P28 -> 0 | J31: =dummy_variables!Q28 -> 1 | K31: =dummy_variables!R28 -> 0 | L31: =dummy_variables!S28 -> 1 | M31: =dummy_variables!T28 -> 0 | N31: =dummy_variables!M28 -> 783672.82
A32: =dummy_variables!E29 -> 52715.1 | B32: =dummy_variables!F29 -> 7223 | C32: =dummy_variables!G29 -> 0.122 | D32: =dummy_variables!I29 -> 84.2 | E32: =dummy_variables!J29 -> 16.15 | F32: =dummy_variables!K29 -> 0 | G32: =dummy_variables!L29 -> 3.7 | H32: =dummy_variables!O29 -> 0 | I32: =dummy_variables!P29 -> 0 | J32: =dummy_variables!Q29 -> 1 | K32: =dummy_variables!R29 -> 0 | L32: =dummy_variables!S29 -> 1 | M32: =dummy_variables!T29 -> 0 | N32: =dummy_variables!M29 -> 701641.97
A33: =dummy_variables!E30 -> 68600.62 | B33: =dummy_variables!F30 -> 3988 | C33: =dummy_variables!G30 -> 0.124 | D33: =dummy_variables!I30 -> 85 | E33: =dummy_variables!J30 -> 0.48 | F33: =dummy_variables!K30 -> 0 | G33: =dummy_variables!L30 -> 3.6 | H33: =dummy_variables!O30 -> 0 | I33: =dummy_variables!P30 -> 0 | J33: =dummy_variables!Q30 -> 0 | K33: =dummy_variables!R30 -> 0 | L33: =dummy_variables!S30 -> 0 | M33: =dummy_variables!T30 -> 1 | N33: =dummy_variables!M30 -> 511844.41
A34: =dummy_variables!E31 -> 63176.73 | B34: =dummy_variables!F31 -> 2390 | C34: =dummy_variables!G31 -> 0.216 | D34: =dummy_variables!I31 -> 87.5 | E34: =dummy_variables!J31 -> 0.31 | F34: =dummy_variables!K31 -> 0 | G34: =dummy_variables!L31 -> 3.1 | H34: =dummy_variables!O31 -> 0 | I34: =dummy_variables!P31 -> 0 | J34: =dummy_variables!Q31 -> 0 | K34: =dummy_variables!R31 -> 0 | L34: =dummy_variables!S31 -> 0 | M34: =dummy_variables!T31 -> 1 | N34: =dummy_variables!M31 -> 537383.79
A35: =dummy_variables!E32 -> 44970.08 | B35: =dummy_variables!F32 -> 2471 | C35: =dummy_variables!G32 -> 0.136 | D35: =dummy_variables!I32 -> 87.6 | E35: =dummy_variables!J32 -> 3.01 | F35: =dummy_variables!K32 -> 1 | G35: =dummy_variables!L32 -> 3.7 | H35: =dummy_variables!O32 -> 0 | I35: =dummy_variables!P32 -> 0 | J35: =dummy_variables!Q32 -> 0 | K35: =dummy_variables!R32 -> 0 | L35: =dummy_variables!S32 -> 0 | M35: =dummy_variables!T32 -> 1 | N35: =dummy_variables!M32 -> 500173.02
A36: =dummy_variables!E33 -> 69816.35 | B36: =dummy_variables!F33 -> 971 | C36: =dummy_variables!G33 -> 0.168 | D36: =dummy_variables!I33 -> 89.9 | E36: =dummy_variables!J33 -> 12.15 | F36: =dummy_variables!K33 -> 0 | G36: =dummy_variables!L33 -> 3.6 | H36: =dummy_variables!O33 -> 0 | I36: =dummy_variables!P33 -> 0 | J36: =dummy_variables!Q33 -> 0 | K36: =dummy_variables!R33 -> 0 | L36: =dummy_variables!S33 -> 0 | M36: =dummy_variables!T33 -> 1 | N36: =dummy_variables!M33 -> 427917.38
... A324: =dummy_variables!E321 -> 40553.11 | B324: =dummy_variables!F321 -> 5317 | C324: =dummy_variables!G321 -> 0.165 | D324: =dummy_variables!I321 -> 84.3 | E324: =dummy_variables!J321 -> 11.82 | F324: =dummy_variables!K321 -> 0 | G324: =dummy_variables!L321 -> 4.1 | H324: =dummy_variables!O321 -> 0 | I324: =dummy_variables!P321 -> 0 | J324: =dummy_variables!Q321 -> 0 | K324: =dummy_variables!R321 -> 0 | L324: =dummy_variables!S321 -> 0 | M324: =dummy_variables!T321 -> 1 | N324: =dummy_variables!M321 -> 559660.84

Sheet prediction_residuals
A1: TASK 7: PREDICTED SALES AND RESIDUALS (using Final Multiple Regression Model)
A3: store_id | B3: month | C3: region | D3: store_type | E3: monthly_sales (actual) | F3: predicted_sales | G3: residual (actual-predicted) | H3: abs_residual
A4: =dummy_variables!A2 -> STR-1001 | B4: =dummy_variables!B2 -> 2025-01-01 | C4: =dummy_variables!C2 -> East | D4: =dummy_variables!D2 -> Residential | E4: =dummy_variables!M2 -> 658832.62 | F4: =multiple_regression!$R$5+multiple_regression!$R$6*dummy_variables!E2+multiple_regression!$R$7*dummy_variables!F2+multiple_regression!$R$8*dummy_variables!G2+multiple_regression!$R$9*dummy_variables!I2+multiple_regression!$R$10*dummy_variables!J2+multiple_regression!$R$11*dummy_variables!K2+multiple_regression!$R$12*dummy_variables!L2+multiple_regression!$R$13*dummy_variables!O2+multiple_regression!$R$14*dummy_variables!P2+multiple_regression!$R$15*dummy_variables!Q2+multiple_regression!$R$16*dummy_variables!R2+multiple_regression!$R$17*dummy_variables!S2+multiple_regression!$R$18*dummy_variables!T2 -> 687401.87 | G4: =E4-F4 -> -28569.255 | H4: =ABS(G4) -> 28569.255
A5: =dummy_variables!A3 -> STR-1001 | B5: =dummy_variables!B3 -> 2025-02-01 | C5: =dummy_variables!C3 -> East | D5: =dummy_variables!D3 -> Residential | E5: =dummy_variables!M3 -> 634436 | F5: =multiple_regression!$R$5+multiple_regression!$R$6*dummy_variables!E3+multiple_regression!$R$7*dummy_variables!F3+multiple_regression!$R$8*dummy_variables!G3+multiple_regression!$R$9*dummy_variables!I3+multiple_regression!$R$10*dummy_variables!J3+multiple_regression!$R$11*dummy_variables!K3+multiple_regression!$R$12*dummy_variables!L3+multiple_regression!$R$13*dummy_variables!O3+multiple_regression!$R$14*dummy_variables!P3+multiple_regression!$R$15*dummy_variables!Q3+multiple_regression!$R$16*dummy_variables!R3+multiple_regression!$R$17*dummy_variables!S3+multiple_regression!$R$18*dummy_variables!T3 -> 670097.63 | G5: =E5-F5 -> -35661.627 | H5: =ABS(G5) -> 35661.627
A6: =dummy_variables!A4 -> STR-1001 | B6: =dummy_variables!B4 -> 2025-03-01 | C6: =dummy_variables!C4 -> East | D6: =dummy_variables!D4 -> Residential | E6: =dummy_variables!M4 -> 678722.06 | F6: =multiple_regression!$R$5+multiple_regression!$R$6*dummy_variables!E4+multiple_regression!$R$7*dummy_variables!F4+multiple_regression!$R$8*dummy_variables!G4+multiple_regression!$R$9*dummy_variables!I4+multiple_regression!$R$10*dummy_variables!J4+multiple_regression!$R$11*dummy_variables!K4+multiple_regression!$R$12*dummy_variables!L4+multiple_regression!$R$13*dummy_variables!O4+multiple_regression!$R$14*dummy_variables!P4+multiple_regression!$R$15*dummy_variables!Q4+multiple_regression!$R$16*dummy_variables!R4+multiple_regression!$R$17*dummy_variables!S4+multiple_regression!$R$18*dummy_variables!T4 -> 701938.58 | G6: =E6-F6 -> -23216.515 | H6: =ABS(G6) -> 23216.515
A7: =dummy_variables!A5 -> STR-1001 | B7: =dummy_variables!B5 -> 2025-04-01 | C7: =dummy_variables!C5 -> East | D7: =dummy_variables!D5 -> Residential | E7: =dummy_variables!M5 -> 658920.3 | F7: =multiple_regression!$R$5+multiple_regression!$R$6*dummy_variables!E5+multiple_regression!$R$7*dummy_variables!F5+multiple_regression!$R$8*dummy_variables!G5+multiple_regression!$R$9*dummy_variables!I5+multiple_regression!$R$10*dummy_variables!J5+multiple_regression!$R$11*dummy_variables!K5+multiple_regression!$R$12*dummy_variables!L5+multiple_regression!$R$13*dummy_variables!O5+multiple_regression!$R$14*dummy_variables!P5+multiple_regression!$R$15*dummy_variables!Q5+multiple_regression!$R$16*dummy_variables!R5+multiple_regression!$R$17*dummy_variables!S5+multiple_regression!$R$18*dummy_variables!T5 -> 731296.32 | G7: =E7-F7 -> -72376.024 | H7: =ABS(G7) -> 72376.024
A8: =dummy_variables!A6 -> STR-1002 | B8: =dummy_variables!B6 -> 2025-01-01 | C8: =dummy_variables!C6 -> East | D8: =dummy_variables!D6 -> High Street | E8: =dummy_variables!M6 -> 741341.44 | F8: =multiple_regression!$R$5+multiple_regression!$R$6*dummy_variables!E6+multiple_regression!$R$7*dummy_variables!F6+multiple_regression!$R$8*dummy_variables!G6+multiple_regression!$R$9*dummy_variables!I6+multiple_regression!$R$10*dummy_variables!J6+multiple_regression!$R$11*dummy_variables!K6+multiple_regression!$R$12*dummy_variables!L6+multiple_regression!$R$13*dummy_variables!O6+multiple_regression!$R$14*dummy_variables!P6+multiple_regression!$R$15*dummy_variables!Q6+multiple_regression!$R$16*dummy_variables!R6+multiple_regression!$R$17*dummy_variables!S6+multiple_regression!$R$18*dummy_variables!T6 -> 789758.43 | G8: =E8-F8 -> -48416.988 | H8: =ABS(G8) -> 48416.988
A9: =dummy_variables!A7 -> STR-1002 | B9: =dummy_variables!B7 -> 2025-02-01 | C9: =dummy_variables!C7 -> East | D9: =dummy_variables!D7 -> High Street | E9: =dummy_variables!M7 -> 761835.34 | F9: =multiple_regression!$R$5+multiple_regression!$R$6*dummy_variables!E7+multiple_regression!$R$7*dummy_variables!F7+multiple_regression!$R$8*dummy_variables!G7+multiple_regression!$R$9*dummy_variables!I7+multiple_regression!$R$10*dummy_variables!J7+multiple_regression!$R$11*dummy_variables!K7+multiple_regression!$R$12*dummy_variables!L7+multiple_regression!$R$13*dummy_variables!O7+multiple_regression!$R$14*dummy_variables!P7+multiple_regression!$R$15*dummy_variables!Q7+multiple_regression!$R$16*dummy_variables!R7+multiple_regression!$R$17*dummy_variables!S7+multiple_regression!$R$18*dummy_variables!T7 -> 781859.37 | G9: =E9-F9 -> -20024.03 | H9: =ABS(G9) -> 20024.03
A10: =dummy_variables!A8 -> STR-1002 | B10: =dummy_variables!B8 -> 2025-03-01 | C10: =dummy_variables!C8 -> East | D10: =dummy_variables!D8 -> High Street | E10: =dummy_variables!M8 -> 806615.54 | F10: =multiple_regression!$R$5+multiple_regression!$R$6*dummy_variables!E8+multiple_regression!$R$7*dummy_variables!F8+multiple_regression!$R$8*dummy_variables!G8+multiple_regression!$R$9*dummy_variables!I8+multiple_regression!$R$10*dummy_variables!J8+multiple_regression!$R$11*dummy_variables!K8+multiple_regression!$R$12*dummy_variables!L8+multiple_regression!$R$13*dummy_variables!O8+multiple_regression!$R$14*dummy_variables!P8+multiple_regression!$R$15*dummy_variables!Q8+multiple_regression!$R$16*dummy_variables!R8+multiple_regression!$R$17*dummy_variables!S8+multiple_regression!$R$18*dummy_variables!T8 -> 811415.17 | G10: =E10-F10 -> -4799.6298 | H10: =ABS(G10) -> 4799.6298
A11: =dummy_variables!A9 -> STR-1002 | B11: =dummy_variables!B9 -> 2025-04-01 | C11: =dummy_variables!C9 -> East | D11: =dummy_variables!D9 -> High Street | E11: =dummy_variables!M9 -> 850164.26 | F11: =multiple_regression!$R$5+multiple_regression!$R$6*dummy_variables!E9+multiple_regression!$R$7*dummy_variables!F9+multiple_regression!$R$8*dummy_variables!G9+multiple_regression!$R$9*dummy_variables!I9+multiple_regression!$R$10*dummy_variables!J9+multiple_regression!$R$11*dummy_variables!K9+multiple_regression!$R$12*dummy_variables!L9+multiple_regression!$R$13*dummy_variables!O9+multiple_regression!$R$14*dummy_variables!P9+multiple_regression!$R$15*dummy_variables!Q9+multiple_regression!$R$16*dummy_variables!R9+multiple_regression!$R$17*dummy_variables!S9+multiple_regression!$R$18*dummy_variables!T9 -> 781844.93 | G11: =E11-F11 -> 68319.327 | H11: =ABS(G11) -> 68319.327
A12: =dummy_variables!A10 -> STR-1003 | B12: =dummy_variables!B10 -> 2025-01-01 | C12: =dummy_variables!C10 -> North | D12: =dummy_variables!D10 -> Airport | E12: =dummy_variables!M10 -> 930581.7 | F12: =multiple_regression!$R$5+multiple_regression!$R$6*dummy_variables!E10+multiple_regression!$R$7*dummy_variables!F10+multiple_regression!$R$8*dummy_variables!G10+multiple_regression!$R$9*dummy_variables!I10+multiple_regression!$R$10*dummy_variables!J10+multiple_regression!$R$11*dummy_variables!K10+multiple_regression!$R$12*dummy_variables!L10+multiple_regression!$R$13*dummy_variables!O10+multiple_regression!$R$14*dummy_variables!P10+multiple_regression!$R$15*dummy_variables!Q10+multiple_regression!$R$16*dummy_variables!R10+multiple_regression!$R$17*dummy_variables!S10+multiple_regression!$R$18*dummy_variables!T10 -> 869060.52 | G12: =E12-F12 -> 61521.175 | H12: =ABS(G12) -> 61521.175
